Workbook

Sheet Products
A1: Product Code | B1: Product Name | C1: Category | D1: Description | E1: Cost Price | F1: Market Price | G1: Selling Price | H1: Profit | I1: Stock Qty | J1: Delivery Fee | K1: COD Available | L1: Photo 1 | M1: Photo 2 | N1: Photo 3 | O1: photo 4 | P1: photo 5 | Q1: Video Link | R1: Facebook Post Link | S1: Supplier | T1: Date Added | U1: Status
A3: P00093 | B3: A9 Mini Wireless Camera | C3: Electronics | E3: 1000 | F3: 1950 | G3: 1450 | H3: =G3-E3 -> 450 | J3: 450 | K3: TRUE | L3: Products_Images/P00093A9 Mini Wireless Camera.Photo 1.113408.jpg | S3: A2Z | T3: 46196 | U3: =IF(I3<=0,"Out of Stock","In Stock") -> Out of Stock
A4: P08391 | B4: S2 Mini WiFi Camera | C4: Electronics | E4: 2050 | F4: 2850 | G4: 2390 | H4: =G4-E4 -> 340 | K4: TRUE | L4: Products_Images/P08391S2 Mini WiFi Camera.Photo 1.170857.png | M4: Products_Images/P08391S2 Mini WiFi Camera.Photo 2.170857.jpg | N4: Products_Images/P08391S2 Mini WiFi Camera.Photo 3.170857.jpg | O4: Products_Images/P08391S2 Mini WiFi Camera.photo 4.170901.jpg | P4: Products_Images/P08391S2 Mini WiFi Camera.photo 5.170901.jpg | T4: 46196 | U4: =IF(I4<=0,"Out of Stock","In Stock") -> Out of Stock
A5: P05995 | B5: Pix-Link WiFi Smart Camera | C5: Electronics | E5: 1900 | F5: 2650 | G5: 2290 | H5: =G5-E5 -> 390 | K5: TRUE | L5: Products_Images/P05995Pix-Link WiFi Smart Camera.Photo 1.044429.jpg | M5: Products_Images/P05995Pix-Link WiFi Smart Camera.Photo 2.044429.jpg | N5: Products_Images/P05995Pix-Link WiFi Smart Camera.Photo 3.044429.jpg | O5: Products_Images/P05995Pix-Link WiFi Smart Camera.photo 4.044438.jpg | T5: 46196 | U5: =IF(I5<=0,"Out of Stock","In Stock") -> Out of Stock
A6: P01832 | B6: K9 Wireless Microphone | C6: Electronics | E6: 1100 | F6: 1590 | G6: 1390 | H6: =G6-E6 -> 290 | K6: TRUE | L6: Products_Images/P01832K9 Wireless Microphone.Photo 1.033246.jpg | T6: 46196 | U6: =IF(I6<=0,"Out of Stock","In Stock") -> Out of Stock
A7: P06779 | B7: K35 Dual Wireless Microphone | C7: Electronics | E7: 1200 | F7: 1650 | G7: 1550 | H7: =G7-E7 -> 350 | K7: TRUE | L7: Products_Images/P06779K35 Dual Wireless Microphone.Photo 1.055224.jpg | M7: Products_Images/P06779K35 Dual Wireless Microphone.Photo 2.055224.jpg | N7: Products_Images/P06779K35 Dual Wireless Microphone.Photo 3.055224.jpg | O7: Products_Images/P06779K35 Dual Wireless Microphone.photo 4.055227.jpg | T7: 46196 | U7: =IF(I7<=0,"Out of Stock","In Stock") -> Out of Stock
A8: P08660 | B8: REMAI PRO88 Wireless Earbud | C8: Electronics | E8: 975 | F8: 1750 | G8: 1560 | H8: =G8-E8 -> 585 | K8: TRUE | L8: Products_Images/P08660REMAI PRO88 Wireless Earbud.Photo 1.174004.png | T8: 46196 | U8: =IF(I8<=0,"Out of Stock","In Stock") -> Out of Stock
A9: P04115 | B9: Y47 Cat Headset | C9: Electronics | E9: 1100 | F9: 1550 | G9: 1390 | H9: =G9-E9 -> 290 | K9: TRUE | L9: Products_Images/P04115Y47 Cat Headset.Photo 1.171757.jpg | T9: 46196 | U9: =IF(I9<=0,"Out of Stock","In Stock") -> Out of Stock
A10: P01469 | B10: T800 Ultra Smart Watch | C10: Electronics | E10: 1300 | F10: 2250 | G10: 1750 | H10: =G10-E10 -> 450 | K10: TRUE | L10: Products_Images/P01469T800 Ultra Smart Watch.Photo 1.133611.jpg | T10: 46196 | U10: =IF(I10<=0,"Out of Stock","In Stock") -> Out of Stock
A11: P00260 | B11: Projection Lamp (Star Light) | C11: Electronics | E11: 850 | F11: 1250 | G11: 1050 | H11: =G11-E11 -> 200 | K11: TRUE | L11: Products_Images/P00260Projection Lamp (Star Light).Photo 1.085224.jpg | M11: Products_Images/P00260Projection Lamp (Star Light).Photo 2.085223.jpg | N11: Products_Images/P00260Projection Lamp (Star Light).Photo 3.085223.jpg | O11: Products_Images/P00260Projection Lamp (Star Light).photo 4.085227.jpg | P11: Products_Images/P00260Projection Lamp (Star Light).photo 5.085228.jpg | T11: 46196 | U11: =IF(I11<=0,"Out of Stock","In Stock") -> Out of Stock
A12: P03400 | B12: Bluetooth Electronic Weight Scale | C12: Electronics | E12: 1200 | F12: 1950 | G12: 1550 | H12: =G12-E12 -> 350 | L12: Products_Images/P03400Bluetooth Electronic Weight Scale.Photo 1.085805.jpg | M12: Products_Images/P03400Bluetooth Electronic Weight Scale.Photo 2.085805.jpg | N12: Products_Images/P03400Bluetooth Electronic Weight Scale.Photo 3.085805.jpg | T12: 46196 | U12: =IF(I12<=0,"Out of Stock","In Stock") -> Out of Stock
A13: P04252 | B13: Smart Wireless Doorbell | C13: Electronics | E13: 900 | H13: =G13-E13 -> -900 | T13: 46196 | U13: =IF(I13<=0,"Out of Stock","In Stock") -> Out of Stock
A14: P02543 | B14: Inflatable Air Sofa With Foot Rest | C14: Home & Living | E14: 3550 | F14: 4360 | H14: =G14-E14 -> -3550 | L14: Products_Images/P02543Inflatable Air Sofa With Foot Rest.Photo 1.174343.jpg | T14: 46196 | U14: =IF(I14<=0,"Out of Stock","In Stock") -> Out of Stock
A15: P05197 | B15: Inflatable Car Air Mattress | C15: Car Accessories | E15: 3700 | F15: 4600 | H15: =G15-E15 -> -3700 | L15: Products_Images/P05197Inflatable Car Air Mattress.Photo 1.174803.jpg | T15: 46196 | U15: =IF(I15<=0,"Out of Stock","In Stock") -> Out of Stock
A16: P07633 | B16: Jewelry Cleaning Machine | C16: Jewelry & Accessories | E16: 850 | F16: 1000 | H16: =G16-E16 -> -850 | L16: Products_Images/P07633Jewelry Cleaning Machine.Photo 1.175115.jpg | T16: 46196 | U16: =IF(I16<=0,"Out of Stock","In Stock") -> Out of Stock
A17: P03951 | B17: K-12 Colorful Karaoke Sound System | C17: Electronics | E17: 1150 | F17: 1600 | G17: 1350 | H17: =G17-E17 -> 200 | L17: Products_Images/P03951K-12 Colorful Karaoke Sound System.Photo 1.090637.jpg | M17: Products_Images/P03951K-12 Colorful Karaoke Sound System.Photo 2.090637.jpg | N17: Products_Images/P03951K-12 Colorful Karaoke Sound System.Photo 3.090637.jpg | O17: Products_Images/P03951K-12 Colorful Karaoke Sound System.photo 4.090639.jpg | T17: 46196 | U17: =IF(I17<=0,"Out of Stock","In Stock") -> Out of Stock
A18: P06077 | B18: KH-740 Fascial Gun Massager | C18: Fitness & Health | E18: 2300 | F18: 2900 | H18: =G18-E18 -> -2300 | L18: Products_Images/P06077KH-740 Fascial Gun Massager.Photo 1.175504.jpg | T18: 46196 | U18: =IF(I18<=0,"Out of Stock","In Stock") -> Out of Stock
A19: P08035 | B19: Modern Square Soap Dispenser | C19: Home & Living | E19: 525 | F19: 650 | H19: =G19-E19 -> -525 | L19: Products_Images/P08035Modern Square Soap Dispenser.Photo 1.175712.jpg | T19: 46196 | U19: =IF(I19<=0,"Out of Stock","In Stock") -> Out of Stock
A20: P01934 | B20: Diamond Crystal Moon Shaped Rechargeable Table Lamp | C20: Home & Living | E20: 1300 | F20: 1900 | H20: =G20-E20 -> -1300 | L20: Products_Images/P01934Diamond Crystal Moon Shaped R_1979645513851130205.Photo 1.175901.jpg | T20: 46196 | U20: =IF(I20<=0,"Out of Stock","In Stock") -> Out of Stock
A21: P00106 | B21: Nima Electric Grinder | C21: Kitchen & Dining | E21: 1300 | F21: 1900 | H21: =G21-E21 -> -1300 | L21: Products_Images/P00106Nima Electric Grinder.Photo 1.180052.jpg | T21: 46196 | U21: =IF(I21<=0,"Out of Stock","In Stock") -> Out of Stock
A22: P01933 | B22: Diamond Crystal Rechargeable Table Lamp | C22: Home & Living | E22: 1300 | F22: 1900 | H22: =G22-E22 -> -1300 | L22: Products_Images/P01933Diamond Crystal Rechargeable Table Lamp.Photo 1.180224.jpg | T22: 46196 | U22: =IF(I22<=0,"Out of Stock","In Stock") -> Out of Stock
A23: P04822 | B23: Diamond Crystal Oval Shaped Rechargeable Table Lamp | C23: Home & Living | E23: 1300 | F23: 1900 | H23: =G23-E23 -> -1300 | L23: Products_Images/P04822Diamond Crystal Oval Shaped R_3741592320910708969.Photo 1.180438.jpg | T23: 46196 | U23: =IF(I23<=0,"Out of Stock","In Stock") -> Out of Stock
A24: P07362 | B24: Pen Laser Pointer | C24: Electronics | E24: 900 | F24: 1600 | G24: 1290 | H24: =G24-E24 -> 390 | L24: Products_Images/P07362Pen Laser Pointer.Photo 1.180559.jpg | T24: 46196 | U24: =IF(I24<=0,"Out of Stock","In Stock") -> Out of Stock
A25: P05944 | B25: Plush Breathing Teddy Bear | C25: Toys & Kids | E25: 1300 | F25: 1700 | G25: 1590 | H25: =G25-E25 -> 290 | L25: Products_Images/P05944Plush Breathing Teddy Bear.Photo 1.180724.jpg | M25: Products_Images/P05944Plush Breathing Teddy Bear.Photo 2.114034.jpg | N25: Products_Images/P05944Plush Breathing Teddy Bear.Photo 3.114034.jpg | O25: Products_Images/P05944Plush Breathing Teddy Bear.photo 4.114034.jpg | T25: 46196 | U25: =IF(I25<=0,"Out of Stock","In Stock") -> Out of Stock
A26: P05676 | B26: Portable Mini Foot Air Pump With Meter | C26: Car Accessories | E26: 1100 | F26: 1550 | H26: =G26-E26 -> -1100 | L26: Products_Images/P05676Portable Mini Foot Air Pump With Meter.Photo 1.180917.jpg | T26: 46196 | U26: =IF(I26<=0,"Out of Stock","In Stock") -> Out of Stock
A27: P04698 | B27: Push Up Board | C27: Fitness & Health | E27: 1650 | F27: 2460 | H27: =G27-E27 -> -1650 | L27: Products_Images/P04698Push Up Board.Photo 1.181409.jpg | T27: 46196 | U27: =IF(I27<=0,"Out of Stock","In Stock") -> Out of Stock
A28: P06002 | B28: Selfie Stick With Fill Light & Remote | C28: Electronics | E28: 650 | F28: 1850 | G28: 1350 | H28: =G28-E28 -> 700 | L28: Products_Images/P06002Selfie Stick With Fill Light & Remote.Photo 1.181927.jpg | T28: 46196 | U28: =IF(I28<=0,"Out of Stock","In Stock") -> Out of Stock
A29: P03596 | B29: Single Bed Foldable Mosquito Net - (L - 5ft , W - 6ft) | C29: Home & Living | E29: 1900 | F29: 2690 | H29: =G29-E29 -> -1900 | L29: Products_Images/P03596Single Bed Foldable Mosquito _6842759353846676944.Photo 1.182351.jpg | T29: 46196 | U29: =IF(I29<=0,"Out of Stock","In Stock") -> Out of Stock
A30: P02671 | B30: Slim & Lift Vest | C30: Fitness & Health | E30: 850 | F30: 1600 | H30: =G30-E30 -> -850 | L30: Products_Images/P02671Slim & Lift Vest.Photo 1.182547.jpg | T30: 46196 | U30: =IF(I30<=0,"Out of Stock","In Stock") -> Out of Stock
A31: P00009 | B31: Solar Sensor Light | C31: Home & Living | E31: 1090 | F31: 1560 | H31: =G31-E31 -> -1090 | L31: Products_Images/P00009Solar Sensor Light.Photo 1.182811.jpg | T31: 46196 | U31: =IF(I31<=0,"Out of Stock","In Stock") -> Out of Stock
A32: P00004 | B32: Solar Street Lamp | C32: Home & Living | E32: 1500 | F32: 2600 | H32: =G32-E32 -> -1500 | L32: Products_Images/P00004Solar Street Lamp.Photo 1.183416.jpg | T32: 46196 | U32: =IF(I32<=0,"Out of Stock","In Stock") -> Out of Stock
A33: P08037 | B33: Stationery Holder - MP | C33: Home & Living | E33: 525 | F33: 1300 | H33: =G33-E33 -> -525 | L33: Products_Images/P08037Stationery Holder - MP.Photo 1.183159.jpg | T33: 46197 | U33: =IF(I33<=0,"Out of Stock","In Stock") -> Out of Stock
A34: P06931 | B34: Stitch Plush Breathing Teddy | C34: Toys & Kids | E34: 1700 | F34: 2500 | H34: =G34-E34 -> -1700 | L34: Products_Images/P06931Stitch Plush Breathing Teddy.Photo 1.183358.jpg | T34: 46197 | U34: =IF(I34<=0,"Out of Stock","In Stock") -> Out of Stock
A35: P08209 | B35: Swan Shaped Crystal LED Lamp | C35: Home & Living | E35: 1300 | F35: 1900 | H35: =G35-E35 -> -1300 | L35: Products_Images/P08209Swan Shaped Crystal LED Lamp.Photo 1.183623.jpg | T35: 46197 | U35: =IF(I35<=0,"Out of Stock","In Stock") -> Out of Stock
A36: P07022 | B36: Transparent Hair Clipper - YX-999 | C36: Beauty & Personal Care | E36: 1000 | F36: 1550 | H36: =G36-E36 -> -1000 | L36: Products_Images/P07022Transparent Hair Clipper - YX-999.Photo 1.183915.jpg | T36: 46197 | U36: =IF(I36<=0,"Out of Stock","In Stock") -> Out of Stock
A37: P04532 | B37: Ultrasonic Aroma Humidifier | C37: Home & Living | E37: 975 | F37: 1690 | G37: 1290 | H37: =G37-E37 -> 315 | L37: Products_Images/P04532Ultrasonic Aroma Humidifier.Photo 1.184041.jpg | T37: 46197 | U37: =IF(I37<=0,"Out of Stock","In Stock") -> Out of Stock
A38: P00151 | B38: USB Juicer | C38: Kitchen & Dining | E38: 900 | F38: 1690 | G38: 1290 | H38: =G38-E38 -> 390 | L38: Products_Images/P00151USB Juicer.Photo 1.184155.jpg | M38: Products_Images/P00151USB Juicer.Photo 2.052423.jpg | N38: Products_Images/P00151USB Juicer.Photo 3.052423.jpg | O38: Products_Images/P00151USB Juicer.photo 4.052423.jpg | T38: 46197 | U38: =IF(I38<=0,"Out of Stock","In Stock") -> Out of Stock
A39: P00679 | B39: Vaccum Flask Set | C39: Kitchen & Dining | E39: 1100 | F39: 1650 | H39: =G39-E39 -> -1100 | L39: Products_Images/P00679Vaccum Flask Set.Photo 1.184336.jpg | T39: 46197 | U39: =IF(I39<=0,"Out of Stock","In Stock") -> Out of Stock
A40: P02549 | B40: Electric Mini Waffle Maker | C40: Kitchen & Dining | E40: 1600 | F40: 2350 | H40: =G40-E40 -> -1600 | L40: Products_Images/P02549Electric Mini Waffle Maker.Photo 1.184522.jpg | T40: 46197 | U40: =IF(I40<=0,"Out of Stock","In Stock") -> Out of Stock
A41: P02528 | B41: Washing Machine Cover | C41: Home & Living | E41: 500 | F41: 1300 | H41: =G41-E41 -> -500 | L41: Products_Images/P02528Washing Machine Cover.Photo 1.184710.jpg | T41: 46197 | U41: =IF(I41<=0,"Out of Stock","In Stock") -> Out of Stock
...

Sheet Orders
A1: Order ID | B1: Date | C1: Customer | D1: Phone | E1: Address | F1: Product Code | G1: Product Name | H1: Qty | I1: Total | J1: Status

Sheet Customers
A1: Customer Name | B1: Phone | C1: City | D1: Total Orders | E1: Last Order Date

Sheet Search
A1: Enter Product Code | B1: Product Name | C1: Selling Price | D1: Stock | E1: Status | F1: Category
B2: =IFERROR(VLOOKUP(A2,Products!A:U,2,FALSE),"Not Found") -> Not Found | C2: =IFERROR(VLOOKUP(A2,Products!A:U,7,FALSE),"") | D2: =IFERROR(VLOOKUP(A2,Products!A:U,9,FALSE),"") | E2: =IFERROR(VLOOKUP(A2,Products!A:U,19,FALSE),"") | F2: =IFERROR(VLOOKUP(A2,Products!A:U,3,FALSE),"")

Sheet Dashboard
A1: ZYRO.LK DASHBOARD
A3: Total Products | B3: =COUNTA(Products!A:A)-1 -> 212
A4: Total Stock | B4: =SUM(Products!I:I) -> 0
A5: Potential Profit | B5: =SUM(Products!H:H) -> -124409
